Total number of GPU: 4
2021-01-13 18:43:40.705257: I tensorflow/stream_executor/platform/default/dso_loader.cc:44] Successfully opened dynamic library libnvinfer.so.6
2021-01-13 18:43:40.707743: I tensorflow/stream_executor/platform/default/dso_loader.cc:44] Successfully opened dynamic library libnvinfer_plugin.so.6
2021-01-13 18:43:41,983	INFO worker.py:651 -- Connecting to existing Ray cluster at address: 128.55.144.49:6379
deep-libs imported TF ver: 2.1.0  elaT=0.0 sec,
Lpd, devCnt= 2 [PhysicalDevice(name='/physical_device:GPU:0', device_type='GPU'), PhysicalDevice(name='/physical_device:GPU:1', device_type='GPU')]
myArg: nodes GPU
myArg: numCPU 30
myArg: numGPU 1
myArg: verb 1
myArg: modelDesign Raytune_design
myArg: rayResult /global/cscratch1/sd/zekailin/ray_results
myArg: numHparams 5
myArg: formatVenue prod
myArg: seedWeights None
myArg: dataPath /global/homes/b/balewski/prjn/neuronBBP-pack40kHzDisc/probe_quad/bbp153/
myArg: probeType quad
myArg: outPath out/
myArg: noXterm False
myArg: trainTime 400
myArg: maxEpochTime 4800
myArg: batch_size None
myArg: steps None
myArg: numFeature None
myArg: useDataFrac 0.05
myArg: dropFrac None
myArg: earlyStopPatience 10
myArg: checkPtOn True
myArg: reduceLRPatience 5
myArg: jobId None
myArg: train_loss_EOE True
myArg: shuffle_data True
myArg: prjName cellSpike
Connecting to Ray head @ cgpu06:6379
Traceback (most recent call last):
  File "/global/homes/z/zekailin/.local/cori/gpu-tensorflow2.1.0-py37/lib/python3.7/site-packages/redis/connection.py", line 552, in connect
    sock = self._connect()
  File "/global/homes/z/zekailin/.local/cori/gpu-tensorflow2.1.0-py37/lib/python3.7/site-packages/redis/connection.py", line 609, in _connect
    raise err
  File "/global/homes/z/zekailin/.local/cori/gpu-tensorflow2.1.0-py37/lib/python3.7/site-packages/redis/connection.py", line 597, in _connect
    sock.connect(socket_address)
ConnectionRefusedError: [Errno 111] Connection refused

During handling of the above exception, another exception occurred:

Traceback (most recent call last):
  File "./train_RayTune.py", line 427, in <module>
    init(address=os.environ["ip_head"])
  File "/global/homes/z/zekailin/.local/cori/gpu-tensorflow2.1.0-py37/lib/python3.7/site-packages/ray/worker.py", line 759, in init
    connect_only=True)
  File "/global/homes/z/zekailin/.local/cori/gpu-tensorflow2.1.0-py37/lib/python3.7/site-packages/ray/node.py", line 143, in __init__
    redis_client.get("session_name"))
  File "/global/homes/z/zekailin/.local/cori/gpu-tensorflow2.1.0-py37/lib/python3.7/site-packages/redis/client.py", line 1579, in get
    return self.execute_command('GET', name)
  File "/global/homes/z/zekailin/.local/cori/gpu-tensorflow2.1.0-py37/lib/python3.7/site-packages/redis/client.py", line 875, in execute_command
    conn = self.connection or pool.get_connection(command_name, **options)
  File "/global/homes/z/zekailin/.local/cori/gpu-tensorflow2.1.0-py37/lib/python3.7/site-packages/redis/connection.py", line 1185, in get_connection
    connection.connect()
  File "/global/homes/z/zekailin/.local/cori/gpu-tensorflow2.1.0-py37/lib/python3.7/site-packages/redis/connection.py", line 557, in connect
    raise ConnectionError(self._error_message(e))
redis.exceptions.ConnectionError: Error 111 connecting to 128.55.144.49:6379. Connection refused.
