Failure # 1 (occurred at 2021-01-11_11-35-17)
Traceback (most recent call last):
  File "/global/homes/z/zekailin/.local/cori/gpu-tensorflow2.1.0-py37/lib/python3.7/site-packages/ray/tune/trial_runner.py", line 726, in _process_trial
    result = self.trial_executor.fetch_result(trial)
  File "/global/homes/z/zekailin/.local/cori/gpu-tensorflow2.1.0-py37/lib/python3.7/site-packages/ray/tune/ray_trial_executor.py", line 489, in fetch_result
    result = ray.get(trial_future[0], timeout=DEFAULT_GET_TIMEOUT)
  File "/global/homes/z/zekailin/.local/cori/gpu-tensorflow2.1.0-py37/lib/python3.7/site-packages/ray/worker.py", line 1452, in get
    raise value.as_instanceof_cause()
ray.exceptions.RayTaskError(TuneError): [36mray::ImplicitFunc.train()[39m (pid=49275, ip=128.55.224.192)
  File "python/ray/_raylet.pyx", line 482, in ray._raylet.execute_task
  File "python/ray/_raylet.pyx", line 436, in ray._raylet.execute_task.function_executor
  File "/global/homes/z/zekailin/.local/cori/gpu-tensorflow2.1.0-py37/lib/python3.7/site-packages/ray/tune/trainable.py", line 336, in train
    result = self.step()
  File "/global/homes/z/zekailin/.local/cori/gpu-tensorflow2.1.0-py37/lib/python3.7/site-packages/ray/tune/function_runner.py", line 374, in step
    ("Wrapped function ran until completion without reporting "
ray.tune.error.TuneError: Wrapped function ran until completion without reporting results or raising an exception.

